<mujoco model="xarm7">
  <compiler angle="radian" meshdir="assets" autolimits="true" />
  <option integrator="implicitfast" />

  <asset>
    <mesh name="link_base" file="link_base.stl"/>
    <mesh name="link1" file="link1.stl"/>
    <mesh name="link2" file="link2.stl"/>
    <mesh name="link3" file="link3.stl"/>
    <mesh name="link4" file="link4.stl"/>
    <mesh name="link5" file="link5.stl"/>
    <mesh name="link6" file="link6.stl"/>
    <mesh name="end_tool" file="end_tool.stl"/>
  </asset>

  <actuator>
    <position joint="joint1" name="joint1" ctrlrange="-3.14 3.14" kp="1000" forcelimited="false" dampratio="1"/>
    <position joint="joint2" name="joint2" ctrlrange="-3.14 3.14" kp="1000" forcelimited="false" dampratio="1"/>
    <position joint="joint3" name="joint3" ctrlrange="-3.14 3.14" kp="1000" forcelimited="false" dampratio="1"/>
    <position joint="joint4" name="joint4" ctrlrange="-3.14 3.14" kp="1000" forcelimited="false" dampratio="1"/>
    <position joint="joint5" name="joint5" ctrlrange="-3.14 3.14" kp="1000" forcelimited="false" dampratio="1"/>
    <position joint="joint6" name="joint6" ctrlrange="-3.14 3.14" kp="1000" forcelimited="false" dampratio="1"/>
    <position joint="joint7" name="joint7" ctrlrange="-3.14 3.14" kp="1000" forcelimited="false" dampratio="1"/>
  </actuator>
  <worldbody>
    <geom type="mesh" rgba="1 1 1 1" mesh="link_base"/>
    <body name="link1" pos="0 0 0.267" gravcomp="1">
      <joint name="joint1" pos="0 0 0" axis="0 0 1" range="-6.28319 6.28319" actuatorfrcrange="-50 50" damping="10" frictionloss="1"/>
      <geom type="mesh" rgba="1 1 1 1" mesh="link1"/>
      <body name="link2" quat="0.707105 -0.707108 0 0" gravcomp="1">
        <joint name="joint2" pos="0 0 0" axis="0 0 1" range="-2.059 2.0944" actuatorfrcrange="-50 50" damping="10" frictionloss="1"/>
        <geom type="mesh" rgba="1 1 1 1" mesh="link2"/>
        <body name="link3" pos="0 -0.293 0" quat="0.707105 0.707108 0 0" gravcomp="1">
          <joint name="joint3" pos="0 0 0" axis="0 0 1" range="-6.28319 6.28319" actuatorfrcrange="-30 30" damping="5" frictionloss="1"/>
          <geom type="mesh" rgba="1 1 1 1" mesh="link3"/>
          <body name="link4" pos="0.0525 0 0" quat="0.707105 0.707108 0 0" gravcomp="1">
            <joint name="joint4" pos="0 0 0" axis="0 0 1" range="-0.19198 3.927" actuatorfrcrange="-30 30" damping="5" frictionloss="1"/>
            <geom type="mesh" rgba="1 1 1 1" mesh="link4"/>
            <body name="link5" pos="0.0775 -0.3425 0" quat="0.707105 0.707108 0 0" gravcomp="1">
              <joint name="joint5" pos="0 0 0" axis="0 0 1" range="-6.28319 6.28319" actuatorfrcrange="-30 30" damping="5" frictionloss="1"/>
              <geom type="mesh" rgba="1 1 1 1" mesh="link5"/>
              <body name="link6" quat="0.707105 0.707108 0 0" gravcomp="1">
                <joint name="joint6" pos="0 0 0" axis="0 0 1" range="-1.69297 3.14159" actuatorfrcrange="-20 20" damping="2" frictionloss="1"/>
                <geom type="mesh" rgba="1 1 1 1" mesh="link6"/>
                <body name="link7" pos="0.076 0.097 0" quat="0.707105 -0.707108 0 0" gravcomp="1">
                  <camera
                    name="wrist_camera"
                    pos="0.05 0 0"
                    fovy="58"
                    mode="fixed"
                    resolution="640 480"
                    euler="3.14 0 -1.57"
                  />
                  <!-- The camera optical frame should be set to the <camera> position rotated 180 degrees about its x-axis -->
                  <site
                    name="wrist_camera_optical_frame"
                    pos="0.05 0 0"
                    euler="0 0 1.57"
                  />
                  <joint name="joint7" pos="0 0 0" axis="0 0 1" range="-6.28319 6.28319" actuatorfrcrange="-20 20" damping="2" frictionloss="1"/>
                  <geom type="mesh" rgba="0.753 0.753 0.753 1" mesh="end_tool"/>
                </body>
              </body>
            </body>
          </body>
        </body>
      </body>
    </body>
  </worldbody>
</mujoco>